<?xml version="1.0" encoding="UTF-8"?>
<!-- Generated by org.testng.reporters.JUnitXMLReporter -->
<testsuite hostname="DESKTOP-NBQRN43" ignored="0" name="testname" tests="3" failures="2" timestamp="2019-11-26T17:26:34 CST" time="0.06" errors="0">
  <testcase name="logdemo" time="0.006" classname="com.auto.testng.TestDemo">
    <failure type="java.lang.RuntimeException" message="自己运行时的异常">
      <![CDATA[java.lang.RuntimeException: 自己运行时的异常
at com.auto.testng.TestDemo.logdemo(TestDemo.java:26)
at java.util.ArrayList.forEach(ArrayList.java:1257)
... Removed 26 stack frames]]>
    </failure>
  </testcase> <!-- logdemo -->
  <testcase name="right" time="0.001" classname="com.auto.testng.TestDemo"/>
  <testcase name="wrong" time="0.001" classname="com.auto.testng.TestDemo">
    <failure type="java.lang.AssertionError" message="expected [2] but found [1]">
      <![CDATA[java.lang.AssertionError: expected [2] but found [1]
at com.auto.testng.TestDemo.wrong(TestDemo.java:19)
at java.util.ArrayList.forEach(ArrayList.java:1257)
... Removed 31 stack frames]]>
    </failure>
  </testcase> <!-- wrong -->
</testsuite> <!-- testname -->
